
Distributed Data Parallel Training IFRNet on Rank 0
2022-11-28 23:16:23:INFO:Namespace(batch_size=55, device=device(type='cuda', index=0), epochs=300, eval_interval=1, label_smoothing=0, local_rank=0, log_path='checkpoint/IFRNet', lr_end=1e-05, lr_start=0.0001, model_name='IFRNet', num_workers=10, resume_epoch=0, resume_path=None, world_size=2)
tensor([[ 0.0501],
        [-0.3887],
        [ 0.3845],
        [-1.7571],
        [ 0.2592],
        [-0.8440],
        [ 1.7525],
        [-0.8753],
        [-1.5809],
        [-0.3249],
        [ 0.9850],
        [-0.8868],
        [ 2.2427],
        [ 0.1920],
        [-0.2292],
        [ 1.0670],
        [ 0.8859],
        [-0.8501],
        [-0.8179],
        [-2.2503],
        [ 0.7014],
        [ 0.3124],
        [-0.5556],
        [ 1.1845],
        [ 0.3519],
        [-0.0244],
        [ 0.3070],
        [ 0.9559],
        [ 0.4686],
        [-0.2566],
        [-1.2806],
        [-0.7864],
        [-1.1346],
        [ 0.0417],
        [ 0.6867],
        [ 0.1229],
        [ 0.3181],
        [ 0.8352],
        [-1.8688],
        [ 0.3686],
        [ 0.5754],
        [-0.9900],
        [ 0.2044],
        [-1.7115],
        [-0.3999],
        [ 0.1209],
        [ 0.6175],
        [ 1.2688],
        [ 0.1978],
        [ 0.9475],
        [-1.0064],
        [-0.2183],
        [-0.0125],
        [ 1.3847],
        [-0.1078]], device='cuda:0', grad_fn=<AddmmBackward0>)
2022-11-28 23:16:34:INFO:Reducer buckets have been rebuilt in this iteration.
/jet/home/kliu8/miniconda3/envs/torch/lib/python3.7/site-packages/torch/autograd/__init__.py:199: UserWarning: Error detected in LogSoftmaxBackward0. Traceback of forward call that caused the error:
  File "train_vimeo90k.py", line 263, in <module>
    train(args, ddp_generator, model, ddp_discriminator)
  File "train_vimeo90k.py", line 120, in train
    gen_disc_loss = GAN_loss(false_labels, gen_discriminator_out)
  File "/jet/home/kliu8/miniconda3/envs/torch/lib/python3.7/site-packages/torch/nn/modules/module.py", line 1190, in _call_impl
    return forward_call(*input, **kwargs)
  File "/jet/home/kliu8/project/IFRNet/models/IFRNet.py", line 264, in forward
    p, q = p.view(-1, p.size(-1)).log(), q.view(-1, q.size(-1)).log_softmax(-1)
  File "/jet/home/kliu8/miniconda3/envs/torch/lib/python3.7/site-packages/torch/fx/traceback.py", line 57, in format_stack
    return traceback.format_stack()
 (Triggered internally at /opt/conda/conda-bld/pytorch_1666643004612/work/torch/csrc/autograd/python_anomaly_mode.cpp:114.)
  allow_unreachable=True, accumulate_grad=True)  # Calls into the C++ engine to run the backward pass
Traceback (most recent call last):
  File "train_vimeo90k.py", line 263, in <module>
    train(args, ddp_generator, model, ddp_discriminator)
  File "train_vimeo90k.py", line 123, in train
    loss_disc.backward()
  File "/jet/home/kliu8/miniconda3/envs/torch/lib/python3.7/site-packages/torch/_tensor.py", line 488, in backward
    self, gradient, retain_graph, create_graph, inputs=inputs
  File "/jet/home/kliu8/miniconda3/envs/torch/lib/python3.7/site-packages/torch/autograd/__init__.py", line 199, in backward
    allow_unreachable=True, accumulate_grad=True)  # Calls into the C++ engine to run the backward pass
RuntimeError: Function 'LogSoftmaxBackward0' returned nan values in its 0th output.